Workbook

Sheet Overview
B2: ZOLA HUNA
B3: Data, Systems & Operations Analyst · E-commerce · Logistics & Aviation · Supply Chain · Retail · IT & Cybersecurity
B4: Johannesburg, South Africa (GMT+2) · zolahuna.zo@gmail.com · +27 65 948 9509 · linkedin.com/in/zola-huna-aa7b51241 · Portfolio: zeehuna.github.io · GitHub: github.com/ZeeHuna
B6: Recruiters: every project below has runnable code, data and charts on GitHub. This workbook shows the Excel side: live formulas, pivot tables, dashboards and a financial model.
B8: # | C8: Project | D8: Certificate / experience applied | E8: Excel skills shown | F8: Tabs
B9: 1 | C9: Air Express Delivery Performance | D9: Google Data Analytics | E9: AVERAGEIFS / COUNTIFS dashboard, charts, pivot (hub × month) | F9: P1 Shipments · P1 Dashboard · Pivot Delivery | K9: Scan: zeehuna.github.io
B10: 2 | C10: E-commerce KPI Model (Power BI) | D10: Microsoft Power BI Advanced | E10: KPI trend table, YoY variance formulas, combo charts | F10: P2 Ecom KPIs
B11: 3 | C11: Security Log Analysis & IR | D11: Google Cybersecurity | E11: Risk scoring formulas, colour-scale heat map, alert log | F11: P3 Security
B12: 4 | C12: SME Network Hardening | D12: Secure Infrastructure Technician | E12: Asset inventory, compliance deltas, pivot (asset type × patch) | F12: P4 Network · Pivot Assets
B13: 5 | C13: Shipment Exception Bot | D13: Python Automation (Angela Yu) | E13: Bot output action list + pivot (exception × severity) | F13: P5 Exceptions · Pivot Exceptions
B14: 6 | C14: IT Service Desk Analytics | D14: IT service management (ITIL 4 practices) | E14: SLA formulas, COUNTIFS Pareto, pivot (category × priority) | F14: P7 Service Desk · P7 Desk Dashboard · Pivot Tickets
B15: 7 | C15: Open Scene Financial Model | D15: My own venture | E15: Live 36-month driver model with scenario selector (INDEX/MATCH, data validation) | F15: P8 Open Scene Model
B16: 8 | C16: Retail Inventory Optimisation | D16: E-commerce retail (50k+ SKUs) | E16: Safety stock & ROP formulas (SQRT, IF), status logic, pivot (ABC × XYZ) | F16: P9 Inventory · Pivot Inventory
B19: Certification / Education | C19: Provider | D19: Year
B20: Google Data Analytics Professional Certificate | C20: Google / Coursera | D20: 2023
B21: Google Cybersecurity Professional Certificate | C21: Google / Coursera | D21: 2025
B22: Secure Infrastructure Technician | C22: Boston City Campus (DHL bursary) | D22: 2025
B23: Microsoft Power BI Advanced | C23: Professional training | D23: 2026
B24: 100 Days of Code: Python | C24: Udemy · Dr Angela Yu | D24: 2026 | H24: On the job at DHL Express, O.R. Tambo
B25: Full-Stack Web Development Bootcamp | C25: Udemy · Dr Angela Yu | D25: 2026
B28: All project data is synthetic (seeded scripts) and modelled on real-world patterns; no employer or customer data is used.

Sheet Project Gallery
A1: Project Gallery · charts, dashboards and screenshots from the GitHub projects
A2: Every image below is generated by the project code at github.com/ZeeHuna (zeehuna.github.io)
A4: 01 Air express delivery analytics | J4: 02 Power BI KPI model
A26: 03 Security log analysis | J26: 04 Network hardening
A48: 05 Shipment exception bot | J48: 06 Open Scene web prototype
A70: 07 IT service desk analytics | J70: 08 Open Scene financial model
A92: 09 Retail inventory optimisation

Sheet P1 Shipments
A1: Project 1 · Air Express Shipments (3,000-row sample)
A2: Google Data Analytics · cleaned data from the Python pipeline · On Time and Days Late are live formulas
A4: Shipment ID | B4: Month | C4: Origin Hub | D4: Service | E4: Segment | F4: Customs | G4: Clearance (h) | H4: Promised Days | I4: Actual Days | J4: Delay Reason | K4: Cost (R) | L4: CSAT | M4: On Time | N4: Days Late
A5: AWB7400011903 | B5: 2026-01 | C5: BFN | D5: Express Worldwide | E5: E-commerce B2C | F5: Y | G5: 21.7 | H5: 3 | I5: 3 | K5: 348.11 | L5: 4 | M5: =IF(I5<=H5,1,0) -> 1 | N5: =MAX(I5-H5,0) -> 0
A6: AWB7400012636 | B6: 2026-01 | C6: JNB | D6: Express 12:00 | E6: E-commerce B2C | F6: Y | G6: 19.3 | H6: 2 | I6: 2 | K6: 270.57 | L6: 4 | M6: =IF(I6<=H6,1,0) -> 1 | N6: =MAX(I6-H6,0) -> 0
A7: AWB7400011287 | B7: 2026-01 | C7: DUR | D7: Economy Select | E7: B2B Account | F7: Y | G7: 6.9 | H7: 5 | I7: 5 | K7: 858.36 | L7: 4 | M7: =IF(I7<=H7,1,0) -> 1 | N7: =MAX(I7-H7,0) -> 0
A8: AWB7400017495 | B8: 2026-01 | C8: JNB | D8: Express 12:00 | E8: E-commerce B2C | F8: Y | G8: 22.8 | H8: 2 | I8: 2 | K8: 304.24 | L8: 4 | M8: =IF(I8<=H8,1,0) -> 1 | N8: =MAX(I8-H8,0) -> 0
A9: AWB7400006147 | B9: 2026-01 | C9: PLZ | D9: Express Worldwide | E9: Healthcare | F9: Y | G9: 13.6 | H9: 3 | I9: 3 | K9: 503.97 | L9: 4 | M9: =IF(I9<=H9,1,0) -> 1 | N9: =MAX(I9-H9,0) -> 0
A10: AWB7400012381 | B10: 2026-01 | C10: JNB | D10: Economy Select | E10: SME | F10: Y | G10: 9.2 | H10: 5 | I10: 4 | K10: 414.06 | L10: 4 | M10: =IF(I10<=H10,1,0) -> 1 | N10: =MAX(I10-H10,0) -> 0
A11: AWB7400012851 | B11: 2026-01 | C11: CPT | D11: Economy Select | E11: B2B Account | F11: Y | G11: 6.8 | H11: 5 | I11: 5 | K11: 508.08 | L11: 4 | M11: =IF(I11<=H11,1,0) -> 1 | N11: =MAX(I11-H11,0) -> 0
A12: AWB7400015394 | B12: 2026-01 | C12: JNB | D12: Express Worldwide | E12: E-commerce B2C | F12: Y | G12: 16.1 | H12: 3 | I12: 3 | K12: 495.58 | L12: 5 | M12: =IF(I12<=H12,1,0) -> 1 | N12: =MAX(I12-H12,0) -> 0
A13: AWB7400009534 | B13: 2026-01 | C13: JNB | D13: Express 12:00 | E13: E-commerce B2C | F13: Y | G13: 14 | H13: 2 | I13: 2 | K13: 345.34 | L13: 5 | M13: =IF(I13<=H13,1,0) -> 1 | N13: =MAX(I13-H13,0) -> 0
A14: AWB7400000937 | B14: 2026-01 | C14: JNB | D14: Express 12:00 | E14: B2B Account | F14: Y | G14: 17.1 | H14: 2 | I14: 1 | K14: 297.04 | L14: 5 | M14: =IF(I14<=H14,1,0) -> 1 | N14: =MAX(I14-H14,0) -> 0
A15: AWB7400016949 | B15: 2026-01 | C15: DUR | D15: Express 9:00 | E15: E-commerce B2C | F15: Y | G15: 22.3 | H15: 2 | I15: 2 | K15: 883.79 | L15: 5 | M15: =IF(I15<=H15,1,0) -> 1 | N15: =MAX(I15-H15,0) -> 0
A16: AWB7400022572 | B16: 2026-01 | C16: JNB | D16: Express 9:00 | E16: E-commerce B2C | F16: Y | G16: 13.3 | H16: 2 | I16: 2 | K16: 693.24 | L16: 4 | M16: =IF(I16<=H16,1,0) -> 1 | N16: =MAX(I16-H16,0) -> 0
... A19: AWB7400010805 | B19: 2026-01 | C19: JNB | D19: Economy Select | E19: E-commerce B2C | F19: Y | G19: 16.2 | H19: 5 | I19: 5 | K19: 346.84 | L19: 5 | M19: =IF(I19<=H19,1,0) -> 1 | N19: =MAX(I19-H19,0) -> 0
A20: AWB7400011213 | B20: 2026-01 | C20: DUR | D20: Express Worldwide | E20: E-commerce B2C | F20: N | G20: 0 | H20: 2 | I20: 4 | J20: Customs documentation | K20: 302.33 | L20: 2 | M20: =IF(I20<=H20,1,0) -> 0 | N20: =MAX(I20-H20,0) -> 2
A21: AWB7400006992 | B21: 2026-01 | C21: CPT | D21: Express Worldwide | E21: E-commerce B2C | F21: Y | G21: 12.9 | H21: 3 | I21: 3 | K21: 303.14 | L21: 5 | M21: =IF(I21<=H21,1,0) -> 1 | N21: =MAX(I21-H21,0) -> 0
A22: AWB7400017654 | B22: 2026-01 | C22: PLZ | D22: Express Worldwide | E22: Healthcare | F22: Y | G22: 5 | H22: 3 | I22: 3 | K22: 339.28 | L22: 5 | M22: =IF(I22<=H22,1,0) -> 1 | N22: =MAX(I22-H22,0) -> 0
A23: AWB7400000553 | B23: 2026-01 | C23: CPT | D23: Express Worldwide | E23: B2B Account | F23: Y | G23: 13.3 | H23: 3 | I23: 6 | J23: Customs documentation | K23: 855.37 | L23: 3 | M23: =IF(I23<=H23,1,0) -> 0 | N23: =MAX(I23-H23,0) -> 3
A24: AWB7400004695 | B24: 2026-01 | C24: BFN | D24: Express Worldwide | E24: E-commerce B2C | F24: Y | G24: 21.5 | H24: 3 | I24: 3 | K24: 286 | L24: 5 | M24: =IF(I24<=H24,1,0) -> 1 | N24: =MAX(I24-H24,0) -> 0
A25: AWB7400017671 | B25: 2026-01 | C25: BFN | D25: Express 12:00 | E25: SME | F25: Y | G25: 24.4 | H25: 2 | I25: 2 | K25: 499.53 | L25: 5 | M25: =IF(I25<=H25,1,0) -> 1 | N25: =MAX(I25-H25,0) -> 0
A26: AWB7400016764 | B26: 2026-01 | C26: PLZ | D26: Economy Select | E26: E-commerce B2C | F26: Y | G26: 21.9 | H26: 5 | I26: 5 | K26: 354.87 | L26: 5 | M26: =IF(I26<=H26,1,0) -> 1 | N26: =MAX(I26-H26,0) -> 0
A27: AWB7400008743 | B27: 2026-01 | C27: JNB | D27: Express Worldwide | E27: E-commerce B2C | F27: Y | G27: 22.3 | H27: 3 | I27: 6 | J27: Incorrect address | K27: 454.2 | L27: 3 | M27: =IF(I27<=H27,1,0) -> 0 | N27: =MAX(I27-H27,0) -> 3
A28: AWB7400010173 | B28: 2026-01 | C28: CPT | D28: Economy Select | E28: Healthcare | F28: Y | G28: 9.1 | H28: 5 | I28: 5 | K28: 358.82 | L28: 5 | M28: =IF(I28<=H28,1,0) -> 1 | N28: =MAX(I28-H28,0) -> 0
A29: AWB7400003569 | B29: 2026-01 | C29: DUR | D29: Express Worldwide | E29: E-commerce B2C | F29: Y | G29: 12.3 | H29: 3 | I29: 2 | K29: 228.6 | L29: 5 | M29: =IF(I29<=H29,1,0) -> 1 | N29: =MAX(I29-H29,0) -> 0
A30: AWB7400015602 | B30: 2026-01 | C30: CPT | D30: Express 12:00 | E30: E-commerce B2C | F30: Y | G30: 20 | H30: 2 | I30: 2 | K30: 343.54 | L30: 4 | M30: =IF(I30<=H30,1,0) -> 1 | N30: =MAX(I30-H30,0) -> 0
A31: AWB7400013168 | B31: 2026-01 | C31: CPT | D31: Express Worldwide | E31: E-commerce B2C | F31: Y | G31: 22.3 | H31: 3 | I31: 5 | J31: Incorrect address | K31: 237.81 | L31: 3 | M31: =IF(I31<=H31,1,0) -> 0 | N31: =MAX(I31-H31,0) -> 2
A32: AWB7400020722 | B32: 2026-01 | C32: PLZ | D32: Express Worldwide | E32: E-commerce B2C | F32: N | G32: 0 | H32: 2 | I32: 2 | K32: 108.36 | L32: 5 | M32: =IF(I32<=H32,1,0) -> 1 | N32: =MAX(I32-H32,0) -> 0
A33: AWB7400002019 | B33: 2026-01 | C33: JNB | D33: Express 9:00 | E33: E-commerce B2C | F33: Y | G33: 15.1 | H33: 2 | I33: 2 | K33: 1004.5 | L33: 5 | M33: =IF(I33<=H33,1,0) -> 1 | N33: =MAX(I33-H33,0) -> 0
A34: AWB7400012603 | B34: 2026-01 | C34: DUR | D34: Express 12:00 | E34: E-commerce B2C | F34: Y | G34: 16.5 | H34: 2 | I34: 5 | J34: Consignee unavailable | K34: 226.7 | L34: 4 | M34: =IF(I34<=H34,1,0) -> 0 | N34: =MAX(I34-H34,0) -> 3
A35: AWB7400011980 | B35: 2026-01 | C35: JNB | D35: Express Worldwide | E35: E-commerce B2C | F35: Y | G35: 19.2 | H35: 3 | I35: 3 | K35: 455.94 | L35: 5 | M35: =IF(I35<=H35,1,0) -> 1 | N35: =MAX(I35-H35,0) -> 0
A36: AWB7400011009 | B36: 2026-01 | C36: JNB | D36: Express 12:00 | E36: B2B Account | F36: Y | G36: 6.7 | H36: 2 | I36: 2 | K36: 322.58 | L36: 4 | M36: =IF(I36<=H36,1,0) -> 1 | N36: =MAX(I36-H36,0) -> 0
A37: AWB7400001425 | B37: 2026-01 | C37: JNB | D37: Economy Select | E37: E-commerce B2C | F37: Y | G37: 20.3 | H37: 5 | I37: 5 | K37: 468.74 | L37: 4 | M37: =IF(I37<=H37,1,0) -> 1 | N37: =MAX(I37-H37,0) -> 0
A38: AWB7400003327 | B38: 2026-01 | C38: DUR | D38: Express 9:00 | E38: E-commerce B2C | F38: Y | G38: 13.8 | H38: 2 | I38: 2 | K38: 677.14 | L38: 5 | M38: =IF(I38<=H38,1,0) -> 1 | N38: =MAX(I38-H38,0) -> 0
A39: AWB7400017633 | B39: 2026-01 | C39: JNB | D39: Express Worldwide | E39: B2B Account | F39: N | G39: 0 | H39: 2 | I39: 2 | K39: 165.99 | L39: 5 | M39: =IF(I39<=H39,1,0) -> 1 | N39: =MAX(I39-H39,0) -> 0
A40: AWB7400015534 | B40: 2026-01 | C40: JNB | D40: Express Worldwide | E40: E-commerce B2C | F40: Y | G40: 14.5 | H40: 3 | I40: 2 | K40: 584.72 | L40: 4 | M40: =IF(I40<=H40,1,0) -> 1 | N40: =MAX(I40-H40,0) -> 0
A41: AWB7400002141 | B41: 2026-01 | C41: JNB | D41: Express Worldwide | E41: B2B Account | F41: Y | G41: 14 | H41: 3 | I41: 3 | K41: 328.92 | L41: 5 | M41: =IF(I41<=H41,1,0) -> 1 | N41: =MAX(I41-H41,0) -> 0
A42: AWB7400018096 | B42: 2026-01 | C42: CPT | D42: Express Worldwide | E42: E-commerce B2C | F42: Y | G42: 26.7 | H42: 3 | I42: 3 | K42: 318.72 | L42: 3 | M42: =IF(I42<=H42,1,0) -> 1 | N42: =MAX(I42-H42,0) -> 0
A43: AWB7400001753 | B43: 2026-01 | C43: CPT | D43: Express Worldwide | E43: B2B Account | F43: Y | G43: 15.5 | H43: 3 | I43: 6 | J43: Customs documentation | K43: 303.21 | L43: 4 | M43: =IF(I43<=H43,1,0) -> 0 | N43: =MAX(I43-H43,0) -> 3
...

Sheet P1 Dashboard
A1: Project 1 · Delivery Performance Dashboard
A2: Every number below is a live formula on 'P1 Shipments'
A4: Shipments | B4: On-Time % | C4: Avg Clearance (h) | D4: Avg CSAT | E4: Revenue (R)
A5: =COUNTA('P1 Shipments'!A5:A3004) -> 3000 | B5: =AVERAGE('P1 Shipments'!M5:M3004) -> 0.90333333 | C5: =AVERAGEIF('P1 Shipments'!F5:F3004,"Y",'P1 Shipments'!G5:G3004) -> 11.308333 | D5: =AVERAGE('P1 Shipments'!L5:L3004) -> 4.361631 | E5: =SUM('P1 Shipments'!K5:K3004) -> 1371026.2
A8: Month | B8: Shipments | C8: On-Time % | D8: Avg Clearance (h)
A9: 2026-01 | B9: =COUNTIF('P1 Shipments'!B5:B3004,A9) -> 496 | C9: =AVERAGEIF('P1 Shipments'!B5:B3004,A9,'P1 Shipments'!M5:M3004) -> 0.8891129 | D9: =AVERAGEIFS('P1 Shipments'!G5:G3004,'P1 Shipments'!B5:B3004,A9,'P1 Shipments'!F5:F3004,"Y") -> 15.826225
A10: 2026-02 | B10: =COUNTIF('P1 Shipments'!B5:B3004,A10) -> 459 | C10: =AVERAGEIF('P1 Shipments'!B5:B3004,A10,'P1 Shipments'!M5:M3004) -> 0.87363834 | D10: =AVERAGEIFS('P1 Shipments'!G5:G3004,'P1 Shipments'!B5:B3004,A10,'P1 Shipments'!F5:F3004,"Y") -> 14.905195
A11: 2026-03 | B11: =COUNTIF('P1 Shipments'!B5:B3004,A11) -> 541 | C11: =AVERAGEIF('P1 Shipments'!B5:B3004,A11,'P1 Shipments'!M5:M3004) -> 0.90942699 | D11: =AVERAGEIFS('P1 Shipments'!G5:G3004,'P1 Shipments'!B5:B3004,A11,'P1 Shipments'!F5:F3004,"Y") -> 11.718894
A12: 2026-04 | B12: =COUNTIF('P1 Shipments'!B5:B3004,A12) -> 461 | C12: =AVERAGEIF('P1 Shipments'!B5:B3004,A12,'P1 Shipments'!M5:M3004) -> 0.9175705 | D12: =AVERAGEIFS('P1 Shipments'!G5:G3004,'P1 Shipments'!B5:B3004,A12,'P1 Shipments'!F5:F3004,"Y") -> 8.6726776
A13: 2026-05 | B13: =COUNTIF('P1 Shipments'!B5:B3004,A13) -> 507 | C13: =AVERAGEIF('P1 Shipments'!B5:B3004,A13,'P1 Shipments'!M5:M3004) -> 0.91518738 | D13: =AVERAGEIFS('P1 Shipments'!G5:G3004,'P1 Shipments'!B5:B3004,A13,'P1 Shipments'!F5:F3004,"Y") -> 8.4326633
A14: 2026-06 | B14: =COUNTIF('P1 Shipments'!B5:B3004,A14) -> 536 | C14: =AVERAGEIF('P1 Shipments'!B5:B3004,A14,'P1 Shipments'!M5:M3004) -> 0.91231343 | D14: =AVERAGEIFS('P1 Shipments'!G5:G3004,'P1 Shipments'!B5:B3004,A14,'P1 Shipments'!F5:F3004,"Y") -> 8.3934831
A17: Delay Reason | B17: Late Shipments | C17: % of Delays | D17: Cumulative %
A18: Customs documentation | B18: =COUNTIF('P1 Shipments'!J5:J3004,A18) -> 88 | C18: =B18/SUM($B$18:$B$24) -> 0.30344828 | D18: =SUM($C$18:C18) -> 0.30344828
A19: Consignee unavailable | B19: =COUNTIF('P1 Shipments'!J5:J3004,A19) -> 48 | C19: =B19/SUM($B$18:$B$24) -> 0.16551724 | D19: =SUM($C$18:C19) -> 0.46896552
A20: Flight capacity | B20: =COUNTIF('P1 Shipments'!J5:J3004,A20) -> 42 | C20: =B20/SUM($B$18:$B$24) -> 0.14482759 | D20: =SUM($C$18:C20) -> 0.6137931
A21: Hub sort backlog | B21: =COUNTIF('P1 Shipments'!J5:J3004,A21) -> 38 | C21: =B21/SUM($B$18:$B$24) -> 0.13103448 | D21: =SUM($C$18:C21) -> 0.74482759
A22: Incorrect address | B22: =COUNTIF('P1 Shipments'!J5:J3004,A22) -> 37 | C22: =B22/SUM($B$18:$B$24) -> 0.12758621 | D22: =SUM($C$18:C22) -> 0.87241379
A23: Duties unpaid | B23: =COUNTIF('P1 Shipments'!J5:J3004,A23) -> 27 | C23: =B23/SUM($B$18:$B$24) -> 0.093103448 | D23: =SUM($C$18:C23) -> 0.96551724
A24: Weather | B24: =COUNTIF('P1 Shipments'!J5:J3004,A24) -> 10 | C24: =B24/SUM($B$18:$B$24) -> 0.034482759 | D24: =SUM($C$18:C24) -> 1

Sheet P2 Ecom KPIs
A1: Project 2 · E-commerce KPI Model (Power BI measures validated in Excel)
A2: Monthly measure values exported from the star schema · YoY and target variance are formulas
A4: YearMonth | B4: Net Revenue (R) | C4: Orders | D4: Avg Order Value (R) | E4: Gross Margin % | F4: On-Time Delivery % | G4: Return Rate % | H4: Perfect Order % | I4: Revenue YoY % | J4: On-Time vs 80% target (pts)
A5: 2025-01 | B5: 2548864.1 | C5: 1805 | D5: 1412.1131 | E5: 0.42555409 | F5: 0.7601108 | G5: 0.079224377 | H5: 0.70747922 | I5: =IF(ROW()-12<5,"",IFERROR(B5/b-7-1,"")) | J5: =(F5-0.8)*100 -> -3.9889197
A6: 2025-02 | B6: 2041818.2 | C6: 1521 | D6: 1342.4183 | E6: 0.42314497 | F6: 0.75345168 | G6: 0.088757396 | H6: 0.69625247 | I6: =IF(ROW()-12<5,"",IFERROR(B6/b-6-1,"")) | J6: =(F6-0.8)*100 -> -4.6548323
A7: 2025-03 | B7: 2529254.7 | C7: 1781 | D7: 1420.1318 | E7: 0.42417444 | F7: 0.75743964 | G7: 0.084783829 | H7: 0.70522179 | I7: =IF(ROW()-12<5,"",IFERROR(B7/b-5-1,"")) | J7: =(F7-0.8)*100 -> -4.2560359
A8: 2025-04 | B8: 2436635.3 | C8: 1761 | D8: 1383.6657 | E8: 0.42074911 | F8: 0.77172061 | G8: 0.082907439 | H8: 0.72004543 | I8: =IF(ROW()-12<5,"",IFERROR(B8/b-4-1,"")) | J8: =(F8-0.8)*100 -> -2.8279387
A9: 2025-05 | B9: 2496410.1 | C9: 1839 | D9: 1357.4824 | E9: 0.41908791 | F9: 0.77324633 | G9: 0.081566069 | H9: 0.71832518 | I9: =IF(ROW()-12<5,"",IFERROR(B9/b-3-1,"")) | J9: =(F9-0.8)*100 -> -2.675367
A10: 2025-06 | B10: 2389127.9 | C10: 1742 | D10: 1371.4856 | E10: 0.4225776 | F10: 0.74856487 | G10: 0.092996556 | H10: 0.68599311 | I10: =IF(ROW()-12<5,"",IFERROR(B10/b-2-1,"")) | J10: =(F10-0.8)*100 -> -5.1435132
A11: 2025-07 | B11: 2365281.7 | C11: 1787 | D11: 1323.6048 | E11: 0.42126003 | F11: 0.77280358 | G11: 0.090095132 | H11: 0.71796307 | I11: =IF(ROW()-12<5,"",IFERROR(B11/b-1-1,"")) | J11: =(F11-0.8)*100 -> -2.7196419
A12: 2025-08 | B12: 2343373.3 | C12: 1831 | D12: 1279.8325 | E12: 0.41997905 | F12: 0.77061715 | G12: 0.079191699 | H12: 0.71873293 | I12: =IF(ROW()-12<5,"",IFERROR(B12/b0-1,"")) | J12: =(F12-0.8)*100 -> -2.9382851
A13: 2025-09 | B13: 2535015.8 | C13: 1774 | D13: 1428.983 | E13: 0.42773142 | F13: 0.74859076 | G13: 0.085682074 | H13: 0.69842165 | I13: =IF(ROW()-12<5,"",IFERROR(B13/B1-1,"")) | J13: =(F13-0.8)*100 -> -5.1409245
A14: 2025-10 | B14: 2541411.4 | C14: 1851 | D14: 1372.9937 | E14: 0.42221487 | F14: 0.75418693 | G14: 0.078336035 | H14: 0.70340357 | I14: =IF(ROW()-12<5,"",IFERROR(B14/B2-1,"")) | J14: =(F14-0.8)*100 -> -4.5813074
A15: 2025-11 | B15: 2817656.3 | C15: 2382 | D15: 1182.8952 | E15: 0.34510355 | F15: 0.68052057 | G15: 0.087321579 | H15: 0.63266163 | I15: =IF(ROW()-12<5,"",IFERROR(B15/B3-1,"")) | J15: =(F15-0.8)*100 -> -11.947943
A16: 2025-12 | B16: 3446814.6 | C16: 2553 | D16: 1350.1036 | E16: 0.42252188 | F16: 0.62122993 | G16: 0.087739914 | H16: 0.57892675 | I16: =IF(ROW()-12<5,"",IFERROR(B16/B4-1,"")) | J16: =(F16-0.8)*100 -> -17.877007
A17: 2026-01 | B17: 2929571.7 | C17: 2167 | D17: 1351.902 | E17: 0.42034812 | F17: 0.8057222 | G17: 0.078449469 | H17: 0.75080757 | I17: =IF(ROW()-12<5,"",IFERROR(B17/B5-1,"")) -> 0.14936363 | J17: =(F17-0.8)*100 -> 0.57221966
A18: 2026-02 | B18: 2623939.1 | C18: 1975 | D18: 1328.5768 | E18: 0.42593872 | F18: 0.80810127 | G18: 0.085063291 | H18: 0.75341772 | I18: =IF(ROW()-12<5,"",IFERROR(B18/B6-1,"")) -> 0.28509928 | J18: =(F18-0.8)*100 -> 0.81012658
A19: 2026-03 | B19: 3004109 | C19: 2173 | D19: 1382.4708 | E19: 0.42122843 | F19: 0.80487805 | G19: 0.083294984 | H19: 0.75011505 | I19: =IF(ROW()-12<5,"",IFERROR(B19/B7-1,"")) -> 0.18774475 | J19: =(F19-0.8)*100 -> 0.48780488
A20: 2026-04 | B20: 2854309.9 | C20: 1989 | D20: 1435.0477 | E20: 0.42180153 | F20: 0.79135244 | G20: 0.086978381 | H20: 0.73001508 | I20: =IF(ROW()-12<5,"",IFERROR(B20/B8-1,"")) -> 0.17141449 | J20: =(F20-0.8)*100 -> -0.86475616
A21: 2026-05 | B21: 3046002.6 | C21: 2227 | D21: 1367.7605 | E21: 0.42163637 | F21: 0.79838348 | G21: 0.072743601 | H21: 0.7467445 | I21: =IF(ROW()-12<5,"",IFERROR(B21/B9-1,"")) -> 0.22015313 | J21: =(F21-0.8)*100 -> -0.16165245
A22: 2026-06 | B22: 2882131.1 | C22: 2065 | D22: 1395.7051 | E22: 0.42173245 | F22: 0.81404358 | G22: 0.078934625 | H22: 0.75932203 | I22: =IF(ROW()-12<5,"",IFERROR(B22/B10-1,"")) -> 0.20635279 | J22: =(F22-0.8)*100 -> 1.4043584

Sheet P3 Security
A1: Project 3 · Security Alerts & NIST CSF Risk Register
A2: Google Cybersecurity · Risk Score = Likelihood × Impact · Rating is a formula
A4: time | B4: rule | C4: severity | D4: source_ip | E4: detail
A5: 2026-09-16 02:10:00 | B5: R1 Brute force | C5: High | D5: 185.220.101.47 | E5: 46 failures in 5 min on srv-web01 (users: admin, root)
A6: 2026-09-16 02:14:30 | B6: R2 Likely compromise | C6: Critical | D6: 185.220.101.47 | E6: SUCCESS as 'admin' on srv-web01 after brute force
A7: 2026-09-16 02:14:30 | B7: R4 Off-hours admin login | C7: Medium | D7: 185.220.101.47 | E7: 'admin' logged in at 02:14 on srv-web01
A8: 2026-09-18 22:40:00 | B8: R3 Password spray | C8: High | D8: 45.95.147.221 | E8: 17 usernames tried on vpn-gw01
A9: 2026-09-19 03:00:00 | B9: R5 Port scan | C9: Medium | D9: 92.118.39.12 | E9: 20 ports x 3 hosts in 10 min (54 denied)
A11: Risk register
A12: risk_id | B12: asset | C12: threat | D12: vulnerability | E12: nist_function | F12: likelihood | G12: impact | H12: control | I12: owner | J12: status | K12: Risk Score | L12: Rating
A13: R01 | B13: Web server (srv-web01) | C13: Credential brute force | D13: Password-only SSH exposed to internet | E13: Protect | F13: 5 | G13: 5 | H13: Key-only SSH + fail2ban + MFA | I13: IT Lead | J13: Open | K13: =F13*G13 -> 25 | L13: =IF(K13>=15,"Critical",IF(K13>=10,"High",IF(K13>=5,"Medium","Low"))) -> Critical
A14: R02 | B14: VPN gateway | C14: Password spraying | D14: No MFA on VPN accounts | E14: Protect | F14: 4 | G14: 5 | H14: Enforce MFA + lockout policy | I14: IT Lead | J14: In progress | K14: =F14*G14 -> 20 | L14: =IF(K14>=15,"Critical",IF(K14>=10,"High",IF(K14>=5,"Medium","Low"))) -> Critical
A15: R03 | B15: File server | C15: Ransomware | D15: Unpatched SMB + flat network | E15: Protect | F15: 3 | G15: 5 | H15: Patch cadence + VLAN segmentation + EDR | I15: IT Lead | J15: In progress | K15: =F15*G15 -> 15 | L15: =IF(K15>=15,"Critical",IF(K15>=10,"High",IF(K15>=5,"Medium","Low"))) -> Critical
A16: R04 | B16: Backups | C16: Backup deletion | D16: Backups on same domain | E16: Recover | F16: 2 | G16: 5 | H16: 3-2-1 with immutable offsite copy | I16: IT Lead | J16: Planned | K16: =F16*G16 -> 10 | L16: =IF(K16>=15,"Critical",IF(K16>=10,"High",IF(K16>=5,"Medium","Low"))) -> High
A17: R05 | B17: Email | C17: Phishing | D17: Low staff awareness | E17: Protect | F17: 4 | G17: 4 | H17: Quarterly phishing simulation + training | I17: HR / IT | J17: Open | K17: =F17*G17 -> 16 | L17: =IF(K17>=15,"Critical",IF(K17>=10,"High",IF(K17>=5,"Medium","Low"))) -> Critical
A18: R06 | B18: Customer data (PII) | C18: POPIA breach | D18: Spreadsheets shared by email | E18: Identify | F18: 3 | G18: 4 | H18: Data classification + DLP rules | I18: Ops Manager | J18: Open | K18: =F18*G18 -> 12 | L18: =IF(K18>=15,"Critical",IF(K18>=10,"High",IF(K18>=5,"Medium","Low"))) -> High
A19: R07 | B19: Firewall | C19: Port scanning / recon | D19: Unused ports open in DMZ | E19: Detect | F19: 4 | G19: 2 | H19: Close unused ports + scan alerts | I19: IT Lead | J19: Closed | K19: =F19*G19 -> 8 | L19: =IF(K19>=15,"Critical",IF(K19>=10,"High",IF(K19>=5,"Medium","Low"))) -> Medium
A20: R08 | B20: Laptops | C20: Device theft | D20: No full-disk encryption | E20: Protect | F20: 2 | G20: 4 | H20: BitLocker + remote wipe | I20: IT Lead | J20: Planned | K20: =F20*G20 -> 8 | L20: =IF(K20>=15,"Critical",IF(K20>=10,"High",IF(K20>=5,"Medium","Low"))) -> Medium
A21: R09 | B21: Admin accounts | C21: Privilege misuse | D21: Shared admin password | E21: Protect | F21: 3 | G21: 4 | H21: Named admin accounts + PAM vault | I21: IT Lead | J21: Open | K21: =F21*G21 -> 12 | L21: =IF(K21>=15,"Critical",IF(K21>=10,"High",IF(K21>=5,"Medium","Low"))) -> High
A22: R10 | B22: Logging | C22: Undetected intrusion | D22: Logs kept 7 days only | E22: Detect | F22: 3 | G22: 3 | H22: Central SIEM with 90-day retention | I22: IT Lead | J22: Planned | K22: =F22*G22 -> 9 | L22: =IF(K22>=15,"Critical",IF(K22>=10,"High",IF(K22>=5,"Medium","Low"))) -> Medium

Sheet P4 Network
A1: Project 4 · Asset Inventory & CIS Controls Scorecard
A2: Secure Infrastructure Technician · improvement = after − before (formula)
A4: Control | B4: CIS Ref | C4: Before % | D4: After % | E4: Improvement (pts)
A5: Inventory of hardware assets | B5: CIS 1 | C5: 0.4 | D5: 1 | E5: =(D5-C5)*100 -> 60
A6: Inventory of software | B6: CIS 2 | C6: 0.25 | D6: 0.9 | E6: =(D6-C6)*100 -> 65
A7: Data protection / encryption | B7: CIS 3 | C7: 0.35 | D7: 0.88 | E7: =(D7-C7)*100 -> 53
A8: Secure configuration baselines | B8: CIS 4 | C8: 0.3 | D8: 0.85 | E8: =(D8-C8)*100 -> 55
A9: Account management | B9: CIS 5 | C9: 0.45 | D9: 0.95 | E9: =(D9-C9)*100 -> 50
A10: Access control & MFA | B10: CIS 6 | C10: 0.2 | D10: 0.9 | E10: =(D10-C10)*100 -> 70
A11: Vulnerability management / patching | B11: CIS 7 | C11: 0.52 | D11: 0.94 | E11: =(D11-C11)*100 -> 42
A12: Audit log management | B12: CIS 8 | C12: 0.25 | D12: 0.8 | E12: =(D12-C12)*100 -> 55
A13: Email & browser protections | B13: CIS 9 | C13: 0.5 | D13: 0.85 | E13: =(D13-C13)*100 -> 35
A14: Malware defences | B14: CIS 10 | C14: 0.7 | D14: 0.95 | E14: =(D14-C14)*100 -> 25
A15: Data recovery (3-2-1 backups) | B15: CIS 11 | C15: 0.4 | D15: 1 | E15: =(D15-C15)*100 -> 60
A16: Network infrastructure mgmt | B16: CIS 12 | C16: 0.35 | D16: 0.9 | E16: =(D16-C16)*100 -> 55
A17: Security awareness training | B17: CIS 14 | C17: 0.15 | D17: 0.75 | E17: =(D17-C17)*100 -> 60
A18: Average maturity | C18: =AVERAGE(C5:C17) -> 0.37076923 | D18: =AVERAGE(D5:D17) -> 0.89769231
A20: Asset inventory
A21: asset_id | B21: type | C21: os_firmware | D21: vlan | E21: owner | F21: criticality | G21: patched_before | H21: patched_after | I21: disk_encrypted
A22: LAP-01 | B22: Laptop | C22: Windows 11 | D22: 10 | E22: Operations | F22: Medium | G22: No | H22: Yes | I22: No
A23: LAP-02 | B23: Laptop | C23: Windows 11 | D23: 10 | E23: Operations | F23: Medium | G23: Yes | H23: Yes | I23: Yes
A24: LAP-03 | B24: Laptop | C24: Windows 11 | D24: 10 | E24: Operations | F24: Medium | G24: Yes | H24: Yes | I24: Yes
A25: LAP-04 | B25: Laptop | C25: Windows 11 | D25: 10 | E25: Operations | F25: Medium | G25: Yes | H25: Yes | I25: Yes
A26: LAP-05 | B26: Laptop | C26: Windows 11 | D26: 10 | E26: Operations | F26: Medium | G26: Yes | H26: Yes | I26: Yes
A27: LAP-06 | B27: Laptop | C27: Windows 11 | D27: 10 | E27: Operations | F27: Medium | G27: Yes | H27: Yes | I27: Yes
A28: LAP-07 | B28: Laptop | C28: Windows 11 | D28: 10 | E28: Operations | F28: Medium | G28: No | H28: No | I28: Yes
A29: LAP-08 | B29: Laptop | C29: Windows 11 | D29: 10 | E29: Operations | F29: Medium | G29: No | H29: Yes | I29: Yes
A30: LAP-09 | B30: Laptop | C30: Windows 11 | D30: 10 | E30: Operations | F30: Medium | G30: Yes | H30: Yes | I30: Yes
A31: LAP-10 | B31: Laptop | C31: Windows 11 | D31: 10 | E31: Operations | F31: Medium | G31: No | H31: Yes | I31: Yes
A32: LAP-11 | B32: Laptop | C32: Windows 11 | D32: 10 | E32: Operations | F32: Medium | G32: Yes | H32: Yes | I32: Yes
A33: LAP-12 | B33: Laptop | C33: Windows 11 | D33: 10 | E33: Operations | F33: Medium | G33: Yes | H33: Yes | I33: No
... A59: DES-08 | B59: Desktop | C59: Windows 10 | D59: 10 | E59: Operations | F59: Low | G59: No | H59: Yes | I59: No
A60: SER-01 | B60: Server | C60: Ubuntu 22.04 | D60: 20 | E60: IT | F60: High | G60: No | H60: Yes
A61: SER-02 | B61: Server | C61: Ubuntu 22.04 | D61: 20 | E61: IT | F61: High | G61: No | H61: Yes
A62: SER-03 | B62: Server | C62: Ubuntu 22.04 | D62: 20 | E62: IT | F62: High | G62: No | H62: Yes
A63: SWI-01 | B63: Switch | C63: Cisco IOS | D63: 99 | E63: IT | F63: High | G63: Yes | H63: Yes
A64: SWI-02 | B64: Switch | C64: Cisco IOS | D64: 99 | E64: IT | F64: High | G64: Yes | H64: Yes
A65: SWI-03 | B65: Switch | C65: Cisco IOS | D65: 99 | E65: IT | F65: High | G65: Yes | H65: Yes
A66: FIR-01 | B66: Firewall | C66: pfSense | D66: 99 | E66: IT | F66: High | G66: Yes | H66: Yes
A67: WIR-01 | B67: Wireless AP | C67: UniFi | D67: 99 | E67: IT | F67: Low | G67: Yes | H67: Yes
...

Sheet P5 Exceptions
A1: Project 5 · Shipment Exception Bot Output
A2: Python automation (openpyxl) · action list produced by exception_bot.py
A4: Severity | B4: Exception | C4: Shipment Id | D4: Customer | E4: Priority | F4: Status | G4: Origin | H4: Destination | I4: Hours Since Scan | J4: Hours To Due | K4: Owner | L4: Action
A5: Critical | B5: SLA breached | C5: AWB8800000430 | D5: PharmaLink SA | E5: Standard | F5: In Transit | G5: FRA | H5: BFN | I5: 6 | J5: -24.4 | K5: Customer Service | L5: Proactive customer update + root-cause code
A6: Critical | B6: SLA breached | C6: AWB8800000330 | D6: AutoParts Hub | E6: Express | F6: Out for Delivery | G6: CPT | H6: JNB | I6: 11.8 | J6: -20.8 | K6: Customer Service | L6: Proactive customer update + root-cause code
A7: Critical | B7: SLA breached | C7: AWB8800000039 | D7: Beauty Box | E7: Standard | F7: Out for Delivery | G7: LHR | H7: JNB | I7: 7.9 | J7: -20 | K7: Customer Service | L7: Proactive customer update + root-cause code
A8: Critical | B8: SLA breached | C8: AWB8800000006 | D8: Online Fashion Co | E8: Express | F8: In Transit | G8: DUR | H8: PLZ | I8: 2.4 | J8: -11.4 | K8: Customer Service | L8: Proactive customer update + root-cause code
A9: Critical | B9: SLA breached | C9: AWB8800000401 | D9: AutoParts Hub | E9: Standard | F9: In Transit | G9: DXB | H9: CPT | I9: 5.4 | J9: -10 | K9: Customer Service | L9: Proactive customer update + root-cause code
A10: Critical | B10: SLA breached | C10: AWB8800000393 | D10: TechDirect | E10: Healthcare | F10: Customs Hold | G10: LHR | H10: DUR | I10: 33.8 | J10: -8.8 | K10: Customer Service | L10: Proactive customer update + root-cause code
A11: Critical | B11: Healthcare shipment at risk | C11: AWB8800000393 | D11: TechDirect | E11: Healthcare | F11: Customs Hold | G11: LHR | H11: DUR | I11: 33.8 | J11: -8.8 | K11: Ops Team Lead | L11: Escalate to duty manager; protect cold-chain / priority handling
A12: Critical | B12: SLA breached | C12: AWB8800000044 | D12: PharmaLink SA | E12: Healthcare | F12: Out for Delivery | G12: FRA | H12: JNB | I12: 4.3 | J12: -7.2 | K12: Customer Service | L12: Proactive customer update + root-cause code
A13: Critical | B13: Healthcare shipment at risk | C13: AWB8800000044 | D13: PharmaLink SA | E13: Healthcare | F13: Out for Delivery | G13: FRA | H13: JNB | I13: 4.3 | J13: -7.2 | K13: Ops Team Lead | L13: Escalate to duty manager; protect cold-chain / priority handling
A14: Critical | B14: SLA breached | C14: AWB8800000402 | D14: Beauty Box | E14: Express | F14: In Transit | G14: DXB | H14: BFN | I14: 12.4 | J14: -5.6 | K14: Customer Service | L14: Proactive customer update + root-cause code
A15: Critical | B15: Customs hold > 48h | C15: AWB8800000461 | D15: AutoParts Hub | E15: Express | F15: Customs Hold | G15: FRA | H15: BFN | I15: 78 | J15: -2.9 | K15: Clearance Team | L15: Chase missing documents / duties with broker and consignee
A16: Critical | B16: SLA breached | C16: AWB8800000461 | D16: AutoParts Hub | E16: Express | F16: Customs Hold | G16: FRA | H16: BFN | I16: 78 | J16: -2.9 | K16: Customer Service | L16: Proactive customer update + root-cause code
... A237: Medium | B237: Address / consignee issue | C237: AWB8800000099 | D237: BookNook | E237: Standard | F237: Consignee Unavailable | G237: DXB | H237: CPT | I237: 4.7 | J237: 84.8 | K237: Customer Service | L237: Contact consignee; confirm address and delivery slot

Sheet P7 Service Desk
A1: Project 6 · IT Service Desk Tickets (2,500-row sample)
A2: IT service management (ITIL 4) · SLA Met is a live formula (resolution ≤ SLA target)
A4: Ticket ID | B4: Created | C4: Month | D4: Category | E4: Priority | F4: Channel | G4: SLA Target (h) | H4: Resolution (h) | I4: FCR | J4: CSAT | K4: Agent | L4: SLA Met
A5: INC105350 | B5: 2026-03-01 01:48 | C5: 2026-03 | D5: Business Apps (ERP/WMS) | E5: P3 | F5: Email | G5: 24 | H5: 41.21 | I5: 0 | J5: 2 | K5: Agent C | L5: =IF(H5<=G5,"Yes","No") -> No
A6: INC101245 | B6: 2026-03-01 03:51 | C6: 2026-03 | D6: Email & Office 365 | E6: P2 | F6: Portal | G6: 8 | H6: 0.4 | I6: 0 | J6: 4 | K6: Agent F | L6: =IF(H6<=G6,"Yes","No") -> Yes
A7: INC103849 | B7: 2026-03-01 04:06 | C7: 2026-03 | D7: Network / VPN | E7: P3 | F7: Email | G7: 24 | H7: 27.17 | I7: 0 | J7: 3 | K7: Agent C | L7: =IF(H7<=G7,"Yes","No") -> No
A8: INC103758 | B8: 2026-03-01 04:43 | C8: 2026-03 | D8: Password / Access | E8: P3 | F8: Phone | G8: 24 | H8: 0.27 | I8: 0 | J8: 5 | K8: Agent D | L8: =IF(H8<=G8,"Yes","No") -> Yes
A9: INC101639 | B9: 2026-03-01 04:48 | C9: 2026-03 | D9: Business Apps (ERP/WMS) | E9: P3 | F9: Email | G9: 24 | H9: 15.07 | I9: 0 | J9: 5 | K9: Agent A | L9: =IF(H9<=G9,"Yes","No") -> Yes
A10: INC103587 | B10: 2026-03-01 07:33 | C10: 2026-03 | D10: Hardware | E10: P3 | F10: Phone | G10: 24 | H10: 10.74 | I10: 0 | J10: 5 | K10: Agent F | L10: =IF(H10<=G10,"Yes","No") -> Yes
A11: INC100560 | B11: 2026-03-01 09:44 | C11: 2026-03 | D11: Security Incident | E11: P2 | F11: Portal | G11: 8 | H11: 1.55 | I11: 0 | J11: 4 | K11: Agent B | L11: =IF(H11<=G11,"Yes","No") -> Yes
A12: INC104031 | B12: 2026-03-01 09:55 | C12: 2026-03 | D12: Printing & Scanners | E12: P4 | F12: Portal | G12: 72 | H12: 9.74 | I12: 1 | J12: 5 | K12: Agent B | L12: =IF(H12<=G12,"Yes","No") -> Yes
A13: INC104057 | B13: 2026-03-01 10:05 | C13: 2026-03 | D13: Hardware | E13: P3 | F13: Portal | G13: 24 | H13: 37.12 | I13: 0 | J13: 3 | K13: Agent B | L13: =IF(H13<=G13,"Yes","No") -> No
A14: INC104292 | B14: 2026-03-01 10:25 | C14: 2026-03 | D14: Printing & Scanners | E14: P3 | F14: Walk-up | G14: 24 | H14: 2.19 | I14: 1 | J14: 5 | K14: Agent E | L14: =IF(H14<=G14,"Yes","No") -> Yes
A15: INC104645 | B15: 2026-03-01 10:42 | C15: 2026-03 | D15: Printing & Scanners | E15: P4 | F15: Email | G15: 72 | H15: 2.86 | I15: 0 | J15: 5 | K15: Agent E | L15: =IF(H15<=G15,"Yes","No") -> Yes
A16: INC103436 | B16: 2026-03-01 11:02 | C16: 2026-03 | D16: Password / Access | E16: P3 | F16: Phone | G16: 24 | H16: 0.21 | I16: 1 | J16: 5 | K16: Agent A | L16: =IF(H16<=G16,"Yes","No") -> Yes
... A2504: INC101796 | B2504: 2026-08-30 22:05 | C2504: 2026-08 | D2504: Password / Access | E2504: P3 | F2504: Email | G2504: 24 | H2504: 0.2788 | I2504: 1 | J2504: 4 | K2504: Agent E | L2504: =IF(H2504<=G2504,"Yes","No") -> Yes

Sheet P7 Desk Dashboard
A1: Project 6 · Service Desk Dashboard
A2: Live COUNTIFS / AVERAGEIFS on 'P7 Service Desk'
A4: Tickets | B4: SLA Met % | C4: FCR % | D4: Median Resolution (h) | E4: Avg CSAT
A5: =COUNTA('P7 Service Desk'!A5:A2504) -> 2500 | B5: =COUNTIF('P7 Service Desk'!L5:L2504,"Yes")/A5 -> 0.9268 | C5: =AVERAGE('P7 Service Desk'!I5:I2504) -> 0.5072 | D5: =MEDIAN('P7 Service Desk'!H5:H2504) -> 2.6939 | E5: =AVERAGE('P7 Service Desk'!J5:J2504) -> 4.3348
A8: Category | B8: Tickets | C8: % of Total | D8: Cumulative % | E8: SLA Met %
A9: Password / Access | B9: =COUNTIF('P7 Service Desk'!D5:D2504,A9) -> 738 | C9: =B9/$A$5 -> 0.2952 | D9: =SUM($C$9:C9) -> 0.2952 | E9: =COUNTIFS('P7 Service Desk'!D5:D2504,A9,'P7 Service Desk'!L5:L2504,"Yes")/B9 -> 1
A10: Business Apps (ERP/WMS) | B10: =COUNTIF('P7 Service Desk'!D5:D2504,A10) -> 405 | C10: =B10/$A$5 -> 0.162 | D10: =SUM($C$9:C10) -> 0.4572 | E10: =COUNTIFS('P7 Service Desk'!D5:D2504,A10,'P7 Service Desk'!L5:L2504,"Yes")/B10 -> 0.92592593
A11: Email & Office 365 | B11: =COUNTIF('P7 Service Desk'!D5:D2504,A11) -> 343 | C11: =B11/$A$5 -> 0.1372 | D11: =SUM($C$9:C11) -> 0.5944 | E11: =COUNTIFS('P7 Service Desk'!D5:D2504,A11,'P7 Service Desk'!L5:L2504,"Yes")/B11 -> 0.99708455
A12: Hardware | B12: =COUNTIF('P7 Service Desk'!D5:D2504,A12) -> 306 | C12: =B12/$A$5 -> 0.1224 | D12: =SUM($C$9:C12) -> 0.7168 | E12: =COUNTIFS('P7 Service Desk'!D5:D2504,A12,'P7 Service Desk'!L5:L2504,"Yes")/B12 -> 0.71568627
A13: Network / VPN | B13: =COUNTIF('P7 Service Desk'!D5:D2504,A13) -> 278 | C13: =B13/$A$5 -> 0.1112 | D13: =SUM($C$9:C13) -> 0.828 | E13: =COUNTIFS('P7 Service Desk'!D5:D2504,A13,'P7 Service Desk'!L5:L2504,"Yes")/B13 -> 0.97122302
A14: Printing & Scanners | B14: =COUNTIF('P7 Service Desk'!D5:D2504,A14) -> 228 | C14: =B14/$A$5 -> 0.0912 | D14: =SUM($C$9:C14) -> 0.9192 | E14: =COUNTIFS('P7 Service Desk'!D5:D2504,A14,'P7 Service Desk'!L5:L2504,"Yes")/B14 -> 0.99122807
A15: New Starter / Leaver | B15: =COUNTIF('P7 Service Desk'!D5:D2504,A15) -> 121 | C15: =B15/$A$5 -> 0.0484 | D15: =SUM($C$9:C15) -> 0.9676 | E15: =COUNTIFS('P7 Service Desk'!D5:D2504,A15,'P7 Service Desk'!L5:L2504,"Yes")/B15 -> 0.58677686
A16: Security Incident | B16: =COUNTIF('P7 Service Desk'!D5:D2504,A16) -> 81 | C16: =B16/$A$5 -> 0.0324 | D16: =SUM($C$9:C16) -> 1 | E16: =COUNTIFS('P7 Service Desk'!D5:D2504,A16,'P7 Service Desk'!L5:L2504,"Yes")/B16 -> 0.9382716
A19: Priority | B19: Target (h) | C19: Tickets | D19: SLA Met %
A20: P1 | B20: 4 | C20: =COUNTIF('P7 Service Desk'!E5:E2504,A20) -> 115 | D20: =COUNTIFS('P7 Service Desk'!E5:E2504,A20,'P7 Service Desk'!L5:L2504,"Yes")/C20 -> 0.8
A21: P2 | B21: 8 | C21: =COUNTIF('P7 Service Desk'!E5:E2504,A21) -> 389 | D21: =COUNTIFS('P7 Service Desk'!E5:E2504,A21,'P7 Service Desk'!L5:L2504,"Yes")/C21 -> 0.85604113
A22: P3 | B22: 24 | C22: =COUNTIF('P7 Service Desk'!E5:E2504,A22) -> 1387 | D22: =COUNTIFS('P7 Service Desk'!E5:E2504,A22,'P7 Service Desk'!L5:L2504,"Yes")/C22 -> 0.93222783
A23: P4 | B23: 72 | C23: =COUNTIF('P7 Service Desk'!E5:E2504,A23) -> 609 | D23: =COUNTIFS('P7 Service Desk'!E5:E2504,A23,'P7 Service Desk'!L5:L2504,"Yes")/C23 -> 0.98357964

Sheet P8 Open Scene Model
A1: Project 7 · Open Scene 36-Month Financial Model (live)
A2: Change the blue inputs or pick a scenario in B5; every month recalculates. ZAR.
A4: Scenario (pick): | B4: Base
A6: Input | B6: Value | C6: Unit | D6: Note
A7: start_creators | B7: 60 | C7: creators | D7: Verified founding creators at launch
A8: start_subscribers | B8: 400 | C8: fans | D8: Paying fans in month 1
A9: new_fans_per_creator | B9: 6 | C9: fans / creator / month | D9: New paying fans each creator brings (decays slowly)
A10: arpu_zar | B10: 119 | C10: ZAR / month | D10: Average subscription price paid per fan
A11: tip_rate | B11: 0.35 | C11: share of fans | D11: Share of paying fans who tip in a month
A12: avg_tip_zar | B12: 80 | C12: ZAR | D12: Average tip / pay-per-view purchase
A13: take_rate | B13: 0.2 | C13: share of GMV | D13: Platform commission (creators keep 80% before fees)
A14: payment_fee_rate | B14: 0.035 | C14: share of GMV | D14: Card / instant-EFT processing
A15: kyc_cost_per_user | B15: 14 | C15: ZAR | D15: ID document + liveness face-match check per new verified user
A16: hosting_base | B16: 18000 | C16: ZAR / month | D16: Cloud hosting and CDN base
A17: hosting_per_user | B17: 3.5 | C17: ZAR / fan / month | D17: Streaming and storage per active fan
A18: moderator_cost | B18: 22000 | C18: ZAR / month | D18: One trust & safety moderator
... A27: churn_high | B27: 0.12 | C27: monthly | D27: Fan churn (conservative)
A29: Scenario | B29: Creator growth | C29: Fan growth multiplier | D29: Monthly churn
A30: Conservative | B30: =$B$22 -> 0.07 | C30: 0.75 | D30: =$B$27 -> 0.12
A31: Base | B31: =$B$23 -> 0.11 | C31: 1 | D31: =$B$26 -> 0.09
A32: Ambitious | B32: =$B$24 -> 0.15 | C32: 1.3 | D32: =$B$25 -> 0.06
A34: Active growth | B34: =INDEX($B$30:$B$32,MATCH($B$4,$A$30:$A$32,0)) -> 0.11
A35: Active fan multiplier | B35: =INDEX($C$30:$C$32,MATCH($B$4,$A$30:$A$32,0)) -> 1
A36: Active churn | B36: =INDEX($D$30:$D$32,MATCH($B$4,$A$30:$A$32,0)) -> 0.09
A38: Creators (m36) | B38: Paying fans (m36) | C38: Year-3 platform revenue | D38: Break-even month | E38: Cash trough
A39: =B78 -> 533.91392 | B39: =D78 -> 15823.431 | C39: =SUM(F67:F78) -> 4634813.4 | D39: =IFERROR(INDEX(A43:A78,MATCH(TRUE(),INDEX(L43:L78>0,0),0)),"Not reached") -> 15 | E39: =MIN(M43:M78) -> -1585864.3
A42: Month | B42: Creators | C42: New Fans | D42: Paying Fans | E42: GMV | F42: Platform Revenue | G42: Creator Payouts | H42: KYC | I42: Hosting | J42: Moderation | K42: Opex | L42: EBITDA | M42: Cumulative Cash
A43: 1 | B43: =$B$7 -> 60 | C43: =B43*$B$9*$B$35*0.985^A43 -> 354.6 | D43: =$B$8*(1-$B$36)+C43 -> 718.6 | E43: =D43*$B$10+D43*$B$11*$B$12 -> 105634.2 | F43: =E43*$B$13 -> 21126.84 | G43: =E43-F43-E43*$B$14 -> 80810.163 | H43: =(C43+B43*$B$34)*$B$15 -> 5056.8 | I43: =$B$16+D43*$B$17 -> 20515.1 | J43: =$B$18*MAX(1,ROUNDUP(B43/$B$19,0)) -> 22000 | K43: =$B$20+I43+J43+H43 -> 142571.9 | L43: =F43-K43 -> -121445.06 | M43: =-$B$21+L43 -> -771445.06
A44: 2 | B44: =B43*(1+$B$34*0.97^A44) -> 66.20994 | C44: =B44*$B$9*$B$35*0.985^A44 -> 385.43123 | D44: =D43*(1-$B$36)+C44 -> 1039.3572 | E44: =D44*$B$10+D44*$B$11*$B$12 -> 152785.51 | F44: =E44*$B$13 -> 30557.103 | G44: =E44-F44-E44*$B$14 -> 116880.92 | H44: =(C44+B44*$B$34)*$B$15 -> 5498.0006 | I44: =$B$16+D44*$B$17 -> 21637.75 | J44: =$B$18*MAX(1,ROUNDUP(B44/$B$19,0)) -> 22000 | K44: =$B$20+I44+J44+H44 -> 144135.75 | L44: =F44-K44 -> -113578.65 | M44: =M43+L44 -> -885023.71
A45: 3 | B45: =B44*(1+$B$34*0.97^A45) -> 72.857023 | C45: =B45*$B$9*$B$35*0.985^A45 -> 417.76434 | D45: =D44*(1-$B$36)+C45 -> 1363.5794 | E45: =D45*$B$10+D45*$B$11*$B$12 -> 200446.17 | F45: =E45*$B$13 -> 40089.235 | G45: =E45-F45-E45*$B$14 -> 153341.32 | H45: =(C45+B45*$B$34)*$B$15 -> 5960.9005 | I45: =$B$16+D45*$B$17 -> 22772.528 | J45: =$B$18*MAX(1,ROUNDUP(B45/$B$19,0)) -> 22000 | K45: =$B$20+I45+J45+H45 -> 145733.43 | L45: =F45-K45 -> -105644.19 | M45: =M44+L45 -> -990667.9
A46: 4 | B46: =B45*(1+$B$34*0.97^A46) -> 79.952001 | C46: =B46*$B$9*$B$35*0.985^A46 -> 451.57044 | D46: =D45*(1-$B$36)+C46 -> 1692.4277 | E46: =D46*$B$10+D46*$B$11*$B$12 -> 248786.87 | F46: =E46*$B$13 -> 49757.375 | G46: =E46-F46-E46*$B$14 -> 190321.96 | H46: =(C46+B46*$B$34)*$B$15 -> 6445.1123 | I46: =$B$16+D46*$B$17 -> 23923.497 | J46: =$B$18*MAX(1,ROUNDUP(B46/$B$19,0)) -> 22000 | K46: =$B$20+I46+J46+H46 -> 147368.61 | L46: =F46-K46 -> -97611.234 | M46: =M45+L46 -> -1088279.1
A47: 5 | B47: =B46*(1+$B$34*0.97^A47) -> 87.504326 | C47: =B47*$B$9*$B$35*0.985^A47 -> 486.81273 | D47: =D46*(1-$B$36)+C47 -> 2026.9219 | E47: =D47*$B$10+D47*$B$11*$B$12 -> 297957.53 | F47: =E47*$B$13 -> 59591.505 | G47: =E47-F47-E47*$B$14 -> 227937.51 | H47: =(C47+B47*$B$34)*$B$15 -> 6950.1349 | I47: =$B$16+D47*$B$17 -> 25094.227 | J47: =$B$18*MAX(1,ROUNDUP(B47/$B$19,0)) -> 22000 | K47: =$B$20+I47+J47+H47 -> 149044.36 | L47: =F47-K47 -> -89452.856 | M47: =M46+L47 -> -1177732
A48: 6 | B48: =B47*(1+$B$34*0.97^A48) -> 95.522078 | C48: =B48*$B$9*$B$35*0.985^A48 -> 523.44661 | D48: =D47*(1-$B$36)+C48 -> 2367.9456 | E48: =D48*$B$10+D48*$B$11*$B$12 -> 348088 | F48: =E48*$B$13 -> 69617.6 | G48: =E48-F48-E48*$B$14 -> 266287.32 | H48: =(C48+B48*$B$34)*$B$15 -> 7475.3566 | I48: =$B$16+D48*$B$17 -> 26287.81 | J48: =$B$18*MAX(1,ROUNDUP(B48/$B$19,0)) -> 22000 | K48: =$B$20+I48+J48+H48 -> 150763.17 | L48: =F48-K48 -> -81145.566 | M48: =M47+L48 -> -1258877.6
A49: 7 | B49: =B48*(1+$B$34*0.97^A49) -> 104.0119 | C49: =B49*$B$9*$B$35*0.985^A49 -> 561.42002 | D49: =D48*(1-$B$36)+C49 -> 2716.2505 | E49: =D49*$B$10+D49*$B$11*$B$12 -> 399288.82 | F49: =E49*$B$13 -> 79857.765 | G49: =E49-F49-E49*$B$14 -> 305455.95 | H49: =(C49+B49*$B$34)*$B$15 -> 8020.0586 | I49: =$B$16+D49*$B$17 -> 27506.877 | J49: =$B$18*MAX(1,ROUNDUP(B49/$B$19,0)) -> 22000 | K49: =$B$20+I49+J49+H49 -> 152526.94 | L49: =F49-K49 -> -72669.171 | M49: =M48+L49 -> -1331546.7
A50: 8 | B50: =B49*(1+$B$34*0.97^A50) -> 112.97895 | C50: =B50*$B$9*$B$35*0.985^A50 -> 600.67371 | D50: =D49*(1-$B$36)+C50 -> 3072.4617 | E50: =D50*$B$10+D50*$B$11*$B$12 -> 451651.87 | F50: =E50*$B$13 -> 90330.373 | G50: =E50-F50-E50*$B$14 -> 345513.68 | H50: =(C50+B50*$B$34)*$B$15 -> 8583.4196 | I50: =$B$16+D50*$B$17 -> 28753.616 | J50: =$B$18*MAX(1,ROUNDUP(B50/$B$19,0)) -> 22000 | K50: =$B$20+I50+J50+H50 -> 154337.04 | L50: =F50-K50 -> -64006.662 | M50: =M49+L50 -> -1395553.4
A51: 9 | B51: =B50*(1+$B$34*0.97^A51) -> 122.42686 | C51: =B51*$B$9*$B$35*0.985^A51 -> 641.14172 | D51: =D50*(1-$B$36)+C51 -> 3437.0818 | E51: =D51*$B$10+D51*$B$11*$B$12 -> 505251.03 | F51: =E51*$B$13 -> 101050.21 | G51: =E51-F51-E51*$B$14 -> 386517.04 | H51: =(C51+B51*$B$34)*$B$15 -> 9164.5215 | I51: =$B$16+D51*$B$17 -> 30029.786 | J51: =$B$18*MAX(1,ROUNDUP(B51/$B$19,0)) -> 22000 | K51: =$B$20+I51+J51+H51 -> 156194.31 | L51: =F51-K51 -> -55144.102 | M51: =M50+L51 -> -1450697.5
A52: 10 | B52: =B51*(1+$B$34*0.97^A52) -> 132.35772 | C52: =B52*$B$9*$B$35*0.985^A52 -> 682.75176 | D52: =D51*(1-$B$36)+C52 -> 3810.4962 | E52: =D52*$B$10+D52*$B$11*$B$12 -> 560142.95 | F52: =E52*$B$13 -> 112028.59 | G52: =E52-F52-E52*$B$14 -> 428509.35 | H52: =(C52+B52*$B$34)*$B$15 -> 9762.3555 | I52: =$B$16+D52*$B$17 -> 31336.737 | J52: =$B$18*MAX(1,ROUNDUP(B52/$B$19,0)) -> 22000 | K52: =$B$20+I52+J52+H52 -> 158099.09 | L52: =F52-K52 -> -46070.503 | M52: =M51+L52 -> -1496768
A53: 11 | B53: =B52*(1+$B$34*0.97^A53) -> 142.77204 | C53: =B53*$B$9*$B$35*0.985^A53 -> 725.42573 | D53: =D52*(1-$B$36)+C53 -> 4192.9773 | E53: =D53*$B$10+D53*$B$11*$B$12 -> 616367.66 | F53: =E53*$B$13 -> 123273.53 | G53: =E53-F53-E53*$B$14 -> 471521.26 | H53: =(C53+B53*$B$34)*$B$15 -> 10375.829 | I53: =$B$16+D53*$B$17 -> 32675.421 | J53: =$B$18*MAX(1,ROUNDUP(B53/$B$19,0)) -> 22000 | K53: =$B$20+I53+J53+H53 -> 160051.25 | L53: =F53-K53 -> -36777.717 | M53: =M52+L53 -> -1533545.7
A54: 12 | B54: =B53*(1+$B$34*0.97^A54) -> 153.66878 | C54: =B54*$B$9*$B$35*0.985^A54 -> 769.08027 | D54: =D53*(1-$B$36)+C54 -> 4584.6896 | E54: =D54*$B$10+D54*$B$11*$B$12 -> 673949.37 | F54: =E54*$B$13 -> 134789.87 | G54: =E54-F54-E54*$B$14 -> 515571.27 | H54: =(C54+B54*$B$34)*$B$15 -> 11003.774 | I54: =$B$16+D54*$B$17 -> 34046.414 | J54: =$B$18*MAX(1,ROUNDUP(B54/$B$19,0)) -> 22000 | K54: =$B$20+I54+J54+H54 -> 162050.19 | L54: =F54-K54 -> -27260.313 | M54: =M53+L54 -> -1560806
A55: 13 | B55: =B54*(1+$B$34*0.97^A55) -> 165.04534 | C55: =B55*$B$9*$B$35*0.985^A55 -> 813.62731 | D55: =D54*(1-$B$36)+C55 -> 4985.6949 | E55: =D55*$B$10+D55*$B$11*$B$12 -> 732897.15 | F55: =E55*$B$13 -> 146579.43 | G55: =E55-F55-E55*$B$14 -> 560666.32 | H55: =(C55+B55*$B$34)*$B$15 -> 11644.952 | I55: =$B$16+D55*$B$17 -> 35449.932 | J55: =$B$18*MAX(1,ROUNDUP(B55/$B$19,0)) -> 22000 | K55: =$B$20+I55+J55+H55 -> 164094.88 | L55: =F55-K55 -> -17515.455 | M55: =M54+L55 -> -1578321.5
...

Sheet P9 Inventory
A1: Project 8 · Retail Inventory Policy (1,200 SKUs)
A2: Safety stock = z × σ × √LT (z by ABC class) · ROP = demand × LT + SS · status logic are live formulas
A4: SKU | B4: Category | C4: Unit Cost | D4: Unit Price | E4: Annual Units | F4: Avg Weekly | G4: CV | H4: ABC | I4: XYZ | J4: Lead Time (wks) | K4: On Hand | L4: Annual Revenue | M4: Service z | N4: Safety Stock | O4: Reorder Point | P4: Weeks Cover | Q4: Status | R4: Stock Value | T4: Status | U4: SKUs | V4: Stock Value (R)
A5: SKU10650 | B5: Kids | C5: 118.84 | D5: 227.63 | E5: 57393 | F5: 1103.712 | G5: 0.836 | H5: A | I5: Y | J5: 3 | K5: 12369 | L5: =E5*D5 -> 13064369 | M5: =IF(H5="A",1.65,IF(H5="B",1.28,0.84)) -> 1.65 | N5: =ROUNDUP(M5*G5*F5*SQRT(J5),0) -> 2637 | O5: =ROUNDUP(F5*J5+N5,0) -> 5949 | P5: =IF(F5>0,K5/F5,99) -> 11.206728 | Q5: =IF(K5<N5,"Stock-out risk",IF(K5<O5,"Reorder now",IF(P5>16,"Overstock","Healthy"))) -> Healthy | R5: =K5*C5 -> 1469932 | T5: Stock-out risk | U5: =COUNTIF($Q$5:$Q$1204,T5) -> 2 | V5: =SUMIF($Q$5:$Q$1204,T5,$R$5:$R$1204) -> 19371.9
A6: SKU11072 | B6: Kids | C6: 103.92 | D6: 267.73 | E6: 17956 | F6: 345.308 | G6: 0.487 | H6: A | I6: X | J6: 2 | K6: 1728 | L6: =E6*D6 -> 4807359.9 | M6: =IF(H6="A",1.65,IF(H6="B",1.28,0.84)) -> 1.65 | N6: =ROUNDUP(M6*G6*F6*SQRT(J6),0) -> 393 | O6: =ROUNDUP(F6*J6+N6,0) -> 1084 | P6: =IF(F6>0,K6/F6,99) -> 5.0042281 | Q6: =IF(K6<N6,"Stock-out risk",IF(K6<O6,"Reorder now",IF(P6>16,"Overstock","Healthy"))) -> Healthy | R6: =K6*C6 -> 179573.76 | T6: Reorder now | U6: =COUNTIF($Q$5:$Q$1204,T6) -> 214 | V6: =SUMIF($Q$5:$Q$1204,T6,$R$5:$R$1204) -> 1921448.1
A7: SKU10503 | B7: Home | C7: 157.02 | D7: 378.4 | E7: 11131 | F7: 214.058 | G7: 0.827 | H7: A | I7: Y | J7: 2 | K7: 1413 | L7: =E7*D7 -> 4211970.4 | M7: =IF(H7="A",1.65,IF(H7="B",1.28,0.84)) -> 1.65 | N7: =ROUNDUP(M7*G7*F7*SQRT(J7),0) -> 414 | O7: =ROUNDUP(F7*J7+N7,0) -> 843 | P7: =IF(F7>0,K7/F7,99) -> 6.6010147 | Q7: =IF(K7<N7,"Stock-out risk",IF(K7<O7,"Reorder now",IF(P7>16,"Overstock","Healthy"))) -> Healthy | R7: =K7*C7 -> 221869.26 | T7: Healthy | U7: =COUNTIF($Q$5:$Q$1204,T7) -> 860 | V7: =SUMIF($Q$5:$Q$1204,T7,$R$5:$R$1204) -> 18373167
A8: SKU10696 | B8: Home | C8: 86.99 | D8: 202.64 | E8: 20679 | F8: 397.673 | G8: 1.069 | H8: A | I8: Z | J8: 2 | K8: 8722 | L8: =E8*D8 -> 4190392.6 | M8: =IF(H8="A",1.65,IF(H8="B",1.28,0.84)) -> 1.65 | N8: =ROUNDUP(M8*G8*F8*SQRT(J8),0) -> 992 | O8: =ROUNDUP(F8*J8+N8,0) -> 1788 | P8: =IF(F8>0,K8/F8,99) -> 21.932593 | Q8: =IF(K8<N8,"Stock-out risk",IF(K8<O8,"Reorder now",IF(P8>16,"Overstock","Healthy"))) -> Overstock | R8: =K8*C8 -> 758726.78 | T8: Overstock | U8: =COUNTIF($Q$5:$Q$1204,T8) -> 124 | V8: =SUMIF($Q$5:$Q$1204,T8,$R$5:$R$1204) -> 7582913.8
A9: SKU10814 | B9: Womenswear | C9: 94.1 | D9: 235.49 | E9: 17344 | F9: 333.538 | G9: 0.329 | H9: A | I9: X | J9: 2 | K9: 2452 | L9: =E9*D9 -> 4084338.6 | M9: =IF(H9="A",1.65,IF(H9="B",1.28,0.84)) -> 1.65 | N9: =ROUNDUP(M9*G9*F9*SQRT(J9),0) -> 257 | O9: =ROUNDUP(F9*J9+N9,0) -> 925 | P9: =IF(F9>0,K9/F9,99) -> 7.3514862 | Q9: =IF(K9<N9,"Stock-out risk",IF(K9<O9,"Reorder now",IF(P9>16,"Overstock","Healthy"))) -> Healthy | R9: =K9*C9 -> 230733.2
A10: SKU10111 | B10: Kids | C10: 110.47 | D10: 261.97 | E10: 15455 | F10: 297.212 | G10: 0.522 | H10: A | I10: Y | J10: 3 | K10: 1094 | L10: =E10*D10 -> 4048746.4 | M10: =IF(H10="A",1.65,IF(H10="B",1.28,0.84)) -> 1.65 | N10: =ROUNDUP(M10*G10*F10*SQRT(J10),0) -> 444 | O10: =ROUNDUP(F10*J10+N10,0) -> 1336 | P10: =IF(F10>0,K10/F10,99) -> 3.6808743 | Q10: =IF(K10<N10,"Stock-out risk",IF(K10<O10,"Reorder now",IF(P10>16,"Overstock","Healthy"))) -> Reorder now | R10: =K10*C10 -> 120854.18
A11: SKU11125 | B11: Home | C11: 144.79 | D11: 272.51 | E11: 14777 | F11: 284.173 | G11: 0.329 | H11: A | I11: X | J11: 3 | K11: 1514 | L11: =E11*D11 -> 4026880.3 | M11: =IF(H11="A",1.65,IF(H11="B",1.28,0.84)) -> 1.65 | N11: =ROUNDUP(M11*G11*F11*SQRT(J11),0) -> 268 | O11: =ROUNDUP(F11*J11+N11,0) -> 1121 | P11: =IF(F11>0,K11/F11,99) -> 5.3277405 | Q11: =IF(K11<N11,"Stock-out risk",IF(K11<O11,"Reorder now",IF(P11>16,"Overstock","Healthy"))) -> Healthy | R11: =K11*C11 -> 219212.06
A12: SKU10357 | B12: Menswear | C12: 462.99 | D12: 1091.3 | E12: 3634 | F12: 69.885 | G12: 0.614 | H12: A | I12: Y | J12: 2 | K12: 630 | L12: =E12*D12 -> 3965784.2 | M12: =IF(H12="A",1.65,IF(H12="B",1.28,0.84)) -> 1.65 | N12: =ROUNDUP(M12*G12*F12*SQRT(J12),0) -> 101 | O12: =ROUNDUP(F12*J12+N12,0) -> 241 | P12: =IF(F12>0,K12/F12,99) -> 9.01481 | Q12: =IF(K12<N12,"Stock-out risk",IF(K12<O12,"Reorder now",IF(P12>16,"Overstock","Healthy"))) -> Healthy | R12: =K12*C12 -> 291683.7
A13: SKU10215 | B13: Womenswear | C13: 83.15 | D13: 157.08 | E13: 25171 | F13: 484.058 | G13: 0.532 | H13: A | I13: Y | J13: 2 | K13: 1793 | L13: =E13*D13 -> 3953860.7 | M13: =IF(H13="A",1.65,IF(H13="B",1.28,0.84)) -> 1.65 | N13: =ROUNDUP(M13*G13*F13*SQRT(J13),0) -> 601 | O13: =ROUNDUP(F13*J13+N13,0) -> 1570 | P13: =IF(F13>0,K13/F13,99) -> 3.7041016 | Q13: =IF(K13<N13,"Stock-out risk",IF(K13<O13,"Reorder now",IF(P13>16,"Overstock","Healthy"))) -> Healthy | R13: =K13*C13 -> 149087.95
A14: SKU10670 | B14: Home | C14: 230.31 | D14: 530.07 | E14: 6658 | F14: 128.038 | G14: 0.542 | H14: A | I14: Y | J14: 4 | K14: 1199 | L14: =E14*D14 -> 3529206.1 | M14: =IF(H14="A",1.65,IF(H14="B",1.28,0.84)) -> 1.65 | N14: =ROUNDUP(M14*G14*F14*SQRT(J14),0) -> 230 | O14: =ROUNDUP(F14*J14+N14,0) -> 743 | P14: =IF(F14>0,K14/F14,99) -> 9.3644074 | Q14: =IF(K14<N14,"Stock-out risk",IF(K14<O14,"Reorder now",IF(P14>16,"Overstock","Healthy"))) -> Healthy | R14: =K14*C14 -> 276141.69
A15: SKU10733 | B15: Kids | C15: 122.9 | D15: 286.92 | E15: 11558 | F15: 222.269 | G15: 1.11 | H15: A | I15: Z | J15: 4 | K15: 4266 | L15: =E15*D15 -> 3316221.4 | M15: =IF(H15="A",1.65,IF(H15="B",1.28,0.84)) -> 1.65 | N15: =ROUNDUP(M15*G15*F15*SQRT(J15),0) -> 815 | O15: =ROUNDUP(F15*J15+N15,0) -> 1705 | P15: =IF(F15>0,K15/F15,99) -> 19.19296 | Q15: =IF(K15<N15,"Stock-out risk",IF(K15<O15,"Reorder now",IF(P15>16,"Overstock","Healthy"))) -> Overstock | R15: =K15*C15 -> 524291.4
A16: SKU10116 | B16: Footwear | C16: 132.1 | D16: 251.73 | E16: 13157 | F16: 253.019 | G16: 0.808 | H16: A | I16: Y | J16: 3 | K16: 1065 | L16: =E16*D16 -> 3312011.6 | M16: =IF(H16="A",1.65,IF(H16="B",1.28,0.84)) -> 1.65 | N16: =ROUNDUP(M16*G16*F16*SQRT(J16),0) -> 585 | O16: =ROUNDUP(F16*J16+N16,0) -> 1345 | P16: =IF(F16>0,K16/F16,99) -> 4.2091701 | Q16: =IF(K16<N16,"Stock-out risk",IF(K16<O16,"Reorder now",IF(P16>16,"Overstock","Healthy"))) -> Reorder now | R16: =K16*C16 -> 140686.5
A17: SKU11087 | B17: Footwear | C17: 134.14 | D17: 322.41 | E17: 10192 | F17: 196 | G17: 0.916 | H17: A | I17: Y | J17: 3 | K17: 1443 | L17: =E17*D17 -> 3286002.7 | M17: =IF(H17="A",1.65,IF(H17="B",1.28,0.84)) -> 1.65 | N17: =ROUNDUP(M17*G17*F17*SQRT(J17),0) -> 514 | O17: =ROUNDUP(F17*J17+N17,0) -> 1102 | P17: =IF(F17>0,K17/F17,99) -> 7.3622449 | Q17: =IF(K17<N17,"Stock-out risk",IF(K17<O17,"Reorder now",IF(P17>16,"Overstock","Healthy"))) -> Healthy | R17: =K17*C17 -> 193564.02
A18: SKU10874 | B18: Home | C18: 135.4 | D18: 293.59 | E18: 11186 | F18: 215.115 | G18: 0.531 | H18: A | I18: Y | J18: 4 | K18: 6345 | L18: =E18*D18 -> 3284097.7 | M18: =IF(H18="A",1.65,IF(H18="B",1.28,0.84)) -> 1.65 | N18: =ROUNDUP(M18*G18*F18*SQRT(J18),0) -> 377 | O18: =ROUNDUP(F18*J18+N18,0) -> 1238 | P18: =IF(F18>0,K18/F18,99) -> 29.495851 | Q18: =IF(K18<N18,"Stock-out risk",IF(K18<O18,"Reorder now",IF(P18>16,"Overstock","Healthy"))) -> Overstock | R18: =K18*C18 -> 859113
A19: SKU10352 | B19: Menswear | C19: 232.12 | D19: 434.02 | E19: 7527 | F19: 144.75 | G19: 0.92 | H19: A | I19: Y | J19: 2 | K19: 371 | L19: =E19*D19 -> 3266868.5 | M19: =IF(H19="A",1.65,IF(H19="B",1.28,0.84)) -> 1.65 | N19: =ROUNDUP(M19*G19*F19*SQRT(J19),0) -> 311 | O19: =ROUNDUP(F19*J19+N19,0) -> 601 | P19: =IF(F19>0,K19/F19,99) -> 2.5630397 | Q19: =IF(K19<N19,"Stock-out risk",IF(K19<O19,"Reorder now",IF(P19>16,"Overstock","Healthy"))) -> Reorder now | R19: =K19*C19 -> 86116.52
A20: SKU10526 | B20: Footwear | C20: 181.1 | D20: 422.83 | E20: 7603 | F20: 146.212 | G20: 0.809 | H20: A | I20: Y | J20: 4 | K20: 803 | L20: =E20*D20 -> 3214776.5 | M20: =IF(H20="A",1.65,IF(H20="B",1.28,0.84)) -> 1.65 | N20: =ROUNDUP(M20*G20*F20*SQRT(J20),0) -> 391 | O20: =ROUNDUP(F20*J20+N20,0) -> 976 | P20: =IF(F20>0,K20/F20,99) -> 5.4920253 | Q20: =IF(K20<N20,"Stock-out risk",IF(K20<O20,"Reorder now",IF(P20>16,"Overstock","Healthy"))) -> Reorder now | R20: =K20*C20 -> 145423.3
... A1204: SKU11046 | B1204: Kids | C1204: 106.19 | D1204: 198.67 | E1204: 0 | F1204: 0 | G1204: 9 | H1204: C | I1204: Z | J1204: 4 | K1204: 0 | L1204: =E1204*D1204 -> 0 | M1204: =IF(H1204="A",1.65,IF(H1204="B",1.28,0.84)) -> 0.84 | N1204: =ROUNDUP(M1204*G1204*F1204*SQRT(J1204),0) -> 0 | O1204: =ROUNDUP(F1204*J1204+N1204,0) -> 0 | P1204: =IF(F1204>0,K1204/F1204,99) -> 99 | Q1204: =IF(K1204<N1204,"Stock-out risk",IF(K1204<O1204,"Reorder now",IF(P1204>16,"Overstock","Healthy"))) -> Overstock | R1204: =K1204*C1204 -> 0

Sheet Pivot Delivery
A1: Pivot Table · Delivery (source: P1 Shipments)
A2: Average on-time rate by origin hub (rows) and month (columns). Format as % in Excel.
A4: Average - On Time | B4: Month
A5: Origin Hub | B5: 2026-01 | C5: 2026-02 | D5: 2026-03 | E5: 2026-04 | F5: 2026-05 | G5: 2026-06 | H5: Total Result
A6: BFN | B6: 1 | C6: 0.88461538 | D6: 1 | E6: 0.88461538 | F6: 0.89655172 | G6: 0.88461538 | H6: 0.9205298
A7: CPT | B7: 0.89380531 | C7: 0.91666667 | D7: 0.88888889 | E7: 0.93636364 | F7: 0.94 | G7: 0.92920354 | H7: 0.91717791
A8: DUR | B8: 0.91428571 | C8: 0.88135593 | D8: 0.89130435 | E8: 0.921875 | F8: 0.91860465 | G8: 0.90425532 | H8: 0.90537634
A9: ELS | B9: 0.85714286 | C9: 0.66666667 | D9: 0.95454545 | E9: 0.80952381 | F9: 0.89285714 | G9: 0.94444444 | H9: 0.86363636
A10: JNB | B10: 0.8826087 | C10: 0.87155963 | D10: 0.91187739 | E10: 0.9245283 | F10: 0.89915966 | G10: 0.89958159 | H10: 0.89842632
A11: PLZ | B11: 0.8125 | C11: 0.81818182 | D11: 0.91891892 | E11: 0.89285714 | F11: 1 | G11: 0.95652174 | H11: 0.9009901
A12: Total Result | B12: 0.8891129 | C12: 0.87363834 | D12: 0.90942699 | E12: 0.9175705 | F12: 0.91518738 | G12: 0.91231343 | H12: 0.90333333

Sheet Pivot Assets
A1: Pivot Table · Assets (source: P4 Network)
A2: Assets by type and post-hardening patch status.
A4: Count - asset_id | B4: patched_after
A5: type | B5: No | C5: Yes | D5: Total Result
A6: CCTV NVR | C6: 1 | D6: 1
A7: Desktop | C7: 8 | D7: 8
A8: Firewall | C8: 1 | D8: 1
A9: Handheld scanner | C9: 12 | D9: 12
A10: Laptop | B10: 1 | C10: 29 | D10: 30
A11: Printer | B11: 1 | C11: 2 | D11: 3
A12: Server | C12: 3 | D12: 3
A13: Switch | C13: 3 | D13: 3
A14: Wireless AP | C14: 4 | D14: 4
A15: Total Result | B15: 2 | C15: 63 | D15: 65

Sheet Pivot Exceptions
A1: Pivot Table · Exceptions (source: P5 Exceptions)
A2: Exception rows by type and severity.
A4: Count - Shipment Id | B4: Severity
A5: Exception | B5: Critical | C5: High | D5: Medium | E5: Total Result
A6: Address / consignee issue | D6: 55 | E6: 55
A7: Customs hold > 48h | B7: 39 | E7: 39
A8: Healthcare shipment at risk | B8: 9 | E8: 9
A9: No scan in 24h | C9: 91 | E9: 91
A10: SLA at risk (<12h to due) | C10: 25 | E10: 25
A11: SLA breached | B11: 14 | E11: 14
A12: Total Result | B12: 62 | C12: 116 | D12: 55 | E12: 233

Sheet Pivot Tickets
A1: Pivot Table · Tickets (source: P7 Service Desk)
A2: Ticket volume by category (rows) and priority (columns).
A4: Count - Ticket ID | B4: Priority
A5: Category | B5: P1 | C5: P2 | D5: P3 | E5: P4 | F5: Total Result
A6: Business Apps (ERP/WMS) | B6: 13 | C6: 59 | D6: 236 | E6: 97 | F6: 405
A7: Email & Office 365 | B7: 16 | C7: 45 | D7: 192 | E7: 90 | F7: 343
A8: Hardware | B8: 13 | C8: 34 | D8: 174 | E8: 85 | F8: 306
A9: Network / VPN | B9: 11 | C9: 40 | D9: 149 | E9: 78 | F9: 278
A10: New Starter / Leaver | B10: 5 | C10: 19 | D10: 70 | E10: 27 | F10: 121
A11: Password / Access | B11: 23 | C11: 107 | D11: 431 | E11: 177 | F11: 738
A12: Printing & Scanners | B12: 8 | C12: 30 | D12: 135 | E12: 55 | F12: 228
A13: Security Incident | B13: 26 | C13: 55 | F13: 81
A14: Total Result | B14: 115 | C14: 389 | D14: 1387 | E14: 609 | F14: 2500

Sheet Pivot Inventory
A1: Pivot Table · Inventory (source: P9 Inventory)
A2: Annual revenue by ABC class (rows) and XYZ variability (columns) — the ABC-XYZ matrix.
A4: Sum - Annual Revenue | B4: XYZ
A5: ABC | B5: X | C5: Y | D5: Z | E5: Total Result
A6: A | B6: 1.124492e+08 | C6: 1.5292947e+08 | D6: 15015687 | E6: 2.8039436e+08
A7: B | B7: 21859369 | C7: 27745804 | D7: 2960957.6 | E7: 52566131
A8: C | B8: 7258558 | C8: 9146172.5 | D8: 1182496.4 | E8: 17587227
A9: Total Result | B9: 1.4156713e+08 | C9: 1.8982145e+08 | D9: 19159141 | E9: 3.5054772e+08
